public class ExceptionHandling3 {

	static void method() throws ArithmeticException  
    {  
        System.out.println("Inside the method()");  
        throw new ArithmeticException("throwing ArithmeticException");  
    }  
	public static void main(String[] args) {
		// TODO Auto-generated method stub
		try  
        {  
            method();  
        }  
        catch(ArithmeticException e)  
        {  
            System.out.println("caught in main() method");  
        }  

	}

}
